Workbook
Name ___Area_de_impresión: Cotización!$B$1:$L$119
Name ___Area_de_impresión: 'OP TELAS'!$B$1:$L$132
Name __Area_de_impresión: 'NV CAJAS (BL)'!$C$13:$S$52
Name _Area_de_impresión: Cotización!$B$1:$L$119
Name _Area_de_impresión: hoja1!$A$1:$H$47
Name _Area_de_impresión: 'NV CAJAS (BL)'!$C$13:$O$60

Sheet Valores
C1: Venta Directa | F1: RC Ferias | I1: Inser
A2: Tela | B2: Valor Mínimo | C2: 3-50 m2 | D2: 51-100 m2 | E2: 101-200 m2 | F2: 3-50 m2 | G2: 51-100 m2 | H2: 101-200 m2 | I2: 3-100 m2 | J2: 101-300 m2
A3: 1104 - Bandera | B3: 35000 | C3: 14000 | D3: 12500 | E3: 10500 | F3: 11000 | G3: 9500 | H3: 8000 | I3: 9500 | J3: 8000
A4: 1106 - Mesh Mate | B4: 36000 | C4: 15000 | D4: 13000 | E4: 11500 | F4: 11500 | G4: 10000 | H4: 9000 | I4: 10000 | J4: 9000
A5: 1107 - Mesh Brillante | B5: 36000 | C5: 15000 | D5: 13000 | E5: 11500 | F5: 11500 | G5: 10000 | H5: 9000 | I5: 10000 | J5: 9000
A6: 1102 - Satín | B6: 40000 | C6: 15500 | D6: 13500 | E6: 12000 | F6: 12000 | G6: 11000 | H6: 10000 | I6: 11000 | J6: 10000
A7: 1108 - Perforado | B7: 40000 | C7: 16000 | D7: 14000 | E7: 12500 | F7: 12500 | G7: 11500 | H7: 10500 | I7: 11500 | J7: 10500
A8: 1109 - Canvas | B8: 40000 | C8: 16500 | D8: 14500 | E8: 13000 | F8: 13000 | G8: 12000 | H8: 11000 | I8: 12000 | J8: 11000
A9: 1140 - Popelina | B9: 45000 | C9: 17000 | D9: 15000 | E9: 14000 | F9: 14000 | G9: 13000 | H9: 12000 | I9: 13000 | J9: 12000
A11: Item de Ingreso | B11: si/no | C11: Fuente | D11: Soporte | E11: Costura
A12: E-Mail | B12: Sí | C12: Directo | D12: Pop Up | E12: Simple
A13: CD/DVD | B13: No | C13: RC Ferias | D13: Roller | E13: Doble
A14: Laser | C14: Inser | D14: Pendón
A15: Otros | D15: Bandera
D16: Panel
D17: Otros

Sheet Nota de venta
B2: Fecha: | G2: COTIZACIÓN Nº- | Z2: CONFIGURACION
B4: DATOS CLIENTE | Z4: Productos: | AC4: Textil | AD4: Ancho | AE4: Valor/M2 | AG4: METROS IMPRESOS EXTRA: | AH4: 0.1 | AJ4: Producto | AK4: Valor unit | AQ4: Productos
B5: Contacto: | H5: Razon Social | Z5: accesorios para colgar | AC5: Popelina 155 | AD5: 1.53 | AE5: 27000 | AJ5: accesorios para colgar | AK5: 7500 | AQ5: Asta fibra de vidrio vela 2 mts
B6: Empresa: | H6: Rut: | Z6: asta vela 3m | AC6: Popelina 310 | AD6: 3.08 | AE6: 31000 | AJ6: asta vela 3m | AK6: 17000 | AQ6: Asta fibra de vidrio vela 3 mts
B7: Email: | H7: Fuente: | Z7: asta vela 4m | AC7: Pearl 155 | AD7: 1.53 | AE7: 23000 | AJ7: asta vela 4m | AK7: 19000 | AQ7: Bandera 2,3x1,5
Z8: banderas | AC8: Pearl 310 | AD8: 3.08 | AE8: 31000 | AJ8: banderas | AK8: 5000 | AQ8: Bandera 3x2
B9: Producto | C9: Textil | D9: Ancho Tela | E9: Ancho | F9: Alto | G9: Cantidad | H9: unid x ancho | I9: ratio | J9: ML impresos | K9: valor x ML | L9: Tema | Z9: base auto | AC9: Pearl 160 HP | AD9: 1.6 | AE9: 23000 | AJ9: base auto | AK9: 11000 | AQ9: Bandera 1,5x1
A10: 1 | D10: =IF(ISTEXT(C10),VLOOKUP(C10,$AC$5:$AE$234,2,FALSE),"") | H10: =IF(ISNUMBER(E10),IF(ROUNDDOWN(D10/E10,0)<1,NotaDeVenta[[#This Row],[Ancho Tela]]/NotaDeVenta[[#This Row],[Ancho]],ROUND(NotaDeVenta[[#This Row],[Ancho Tela]]/NotaDeVenta[[#This Row],[Ancho]],0)),"") | I10: =IF(ISNUMBER(H10),G10/H10,"") | J10: =IF(ISNUMBER(G10),IF(OR(B10="Textil Backlight",B10="Caja + Backlight"),E10*F10*G10,F10*I10),0) -> 0 | K10: =IF(ISTEXT(C10),VLOOKUP(C10,$AC$5:$AE$234,3,FALSE),"") | L10: Tema | Z10: base suelo metal más accesorio | AC10: Bistretch | AD10: 1.48 | AE10: 11000 | AJ10: base suelo metal más accesorio | AK10: 15000 | AQ10: Base auto
A11: 2 | D11: =IF(ISTEXT(C11),VLOOKUP(C11,$AC$5:$AE$234,2,FALSE),"") | H11: =IF(ISNUMBER(E11),IF(ROUNDDOWN(D11/E11,0)<1,NotaDeVenta[[#This Row],[Ancho Tela]]/NotaDeVenta[[#This Row],[Ancho]],ROUND(NotaDeVenta[[#This Row],[Ancho Tela]]/NotaDeVenta[[#This Row],[Ancho]],0)),"") | I11: =IF(ISNUMBER(H11),G11/H11,"") | J11: =IF(ISNUMBER(G11),IF(OR(B11="Textil Backlight",B11="Caja + Backlight"),E11*F11*G11,F11*I11),0) -> 0 | K11: =IF(ISTEXT(C11),VLOOKUP(C11,$AC$5:$AE$234,3,FALSE),"")
A12: 3 | D12: =IF(ISTEXT(C12),VLOOKUP(C12,$AC$5:$AE$234,2,FALSE),"") | H12: =IF(ISNUMBER(E12),IF(ROUNDDOWN(D12/E12,0)<1,NotaDeVenta[[#This Row],[Ancho Tela]]/NotaDeVenta[[#This Row],[Ancho]],ROUND(NotaDeVenta[[#This Row],[Ancho Tela]]/NotaDeVenta[[#This Row],[Ancho]],0)),"") | I12: =IF(ISNUMBER(H12),G12/H12,"") | J12: =IF(ISNUMBER(G12),IF(OR(B12="Textil Backlight",B12="Caja + Backlight"),E12*F12*G12,F12*I12),0) -> 0 | K12: =IF(ISTEXT(C12),VLOOKUP(C12,$AC$5:$AE$234,3,FALSE),"")
A13: 4 | D13: =IF(ISTEXT(C13),VLOOKUP(C13,$AC$5:$AE$234,2,FALSE),"") | H13: =IF(ISNUMBER(E13),IF(ROUNDDOWN(D13/E13,0)<1,NotaDeVenta[[#This Row],[Ancho Tela]]/NotaDeVenta[[#This Row],[Ancho]],ROUND(NotaDeVenta[[#This Row],[Ancho Tela]]/NotaDeVenta[[#This Row],[Ancho]],0)),"") | I13: =IF(ISNUMBER(H13),G13/H13,"") | J13: =IF(ISNUMBER(G13),IF(OR(B13="Textil Backlight",B13="Caja + Backlight"),E13*F13*G13,F13*I13),0) -> 0 | K13: =IF(ISTEXT(C13),VLOOKUP(C13,$AC$5:$AE$234,3,FALSE),"")
A14: 5 | D14: =IF(ISTEXT(C14),VLOOKUP(C14,$AC$5:$AE$234,2,FALSE),"") | H14: =IF(ISNUMBER(E14),IF(ROUNDDOWN(D14/E14,0)<1,NotaDeVenta[[#This Row],[Ancho Tela]]/NotaDeVenta[[#This Row],[Ancho]],ROUND(NotaDeVenta[[#This Row],[Ancho Tela]]/NotaDeVenta[[#This Row],[Ancho]],0)),"") | I14: =IF(ISNUMBER(H14),G14/H14,"") | J14: =IF(ISNUMBER(G14),IF(OR(B14="Textil Backlight",B14="Caja + Backlight"),E14*F14*G14,F14*I14),0) -> 0 | K14: =IF(ISTEXT(C14),VLOOKUP(C14,$AC$5:$AE$234,3,FALSE),"")
A15: 6 | D15: =IF(ISTEXT(C15),VLOOKUP(C15,$AC$5:$AE$234,2,FALSE),"") | H15: =IF(ISNUMBER(E15),IF(ROUNDDOWN(D15/E15,0)<1,NotaDeVenta[[#This Row],[Ancho Tela]]/NotaDeVenta[[#This Row],[Ancho]],ROUND(NotaDeVenta[[#This Row],[Ancho Tela]]/NotaDeVenta[[#This Row],[Ancho]],0)),"") | I15: =IF(ISNUMBER(H15),G15/H15,"") | J15: =IF(ISNUMBER(G15),IF(OR(B15="Textil Backlight",B15="Caja + Backlight"),E15*F15*G15,F15*I15),0) -> 0 | K15: =IF(ISTEXT(C15),VLOOKUP(C15,$AC$5:$AE$234,3,FALSE),"")
A16: 7 | D16: =IF(ISTEXT(C16),VLOOKUP(C16,$AC$5:$AE$234,2,FALSE),"") | H16: =IF(ISNUMBER(E16),IF(ROUNDDOWN(D16/E16,0)<1,NotaDeVenta[[#This Row],[Ancho Tela]]/NotaDeVenta[[#This Row],[Ancho]],ROUND(NotaDeVenta[[#This Row],[Ancho Tela]]/NotaDeVenta[[#This Row],[Ancho]],0)),"") | I16: =IF(ISNUMBER(H16),G16/H16,"") | J16: =IF(ISNUMBER(G16),IF(OR(B16="Textil Backlight",B16="Caja + Backlight"),E16*F16*G16,F16*I16),0) -> 0 | K16: =IF(ISTEXT(C16),VLOOKUP(C16,$AC$5:$AE$234,3,FALSE),"")
A17: 8 | D17: =IF(ISTEXT(C17),VLOOKUP(C17,$AC$5:$AE$234,2,FALSE),"") | H17: =IF(ISNUMBER(E17),IF(ROUNDDOWN(D17/E17,0)<1,NotaDeVenta[[#This Row],[Ancho Tela]]/NotaDeVenta[[#This Row],[Ancho]],ROUND(NotaDeVenta[[#This Row],[Ancho Tela]]/NotaDeVenta[[#This Row],[Ancho]],0)),"") | I17: =IF(ISNUMBER(H17),G17/H17,"") | J17: =IF(ISNUMBER(G17),IF(OR(B17="Textil Backlight",B17="Caja + Backlight"),E17*F17*G17,F17*I17),0) -> 0 | K17: =IF(ISTEXT(C17),VLOOKUP(C17,$AC$5:$AE$234,3,FALSE),"")
A18: 9 | D18: =IF(ISTEXT(C18),VLOOKUP(C18,$AC$5:$AE$234,2,FALSE),"") | H18: =IF(ISNUMBER(E18),IF(ROUNDDOWN(D18/E18,0)<1,NotaDeVenta[[#This Row],[Ancho Tela]]/NotaDeVenta[[#This Row],[Ancho]],ROUND(NotaDeVenta[[#This Row],[Ancho Tela]]/NotaDeVenta[[#This Row],[Ancho]],0)),"") | I18: =IF(ISNUMBER(H18),G18/H18,"") | J18: =IF(ISNUMBER(G18),IF(OR(B18="Textil Backlight",B18="Caja + Backlight"),E18*F18*G18,F18*I18),0) -> 0 | K18: =IF(ISTEXT(C18),VLOOKUP(C18,$AC$5:$AE$234,3,FALSE),"")
A19: 10 | D19: =IF(ISTEXT(C19),VLOOKUP(C19,$AC$5:$AE$234,2,FALSE),"") | H19: =IF(ISNUMBER(E19),IF(ROUNDDOWN(D19/E19,0)<1,NotaDeVenta[[#This Row],[Ancho Tela]]/NotaDeVenta[[#This Row],[Ancho]],ROUND(NotaDeVenta[[#This Row],[Ancho Tela]]/NotaDeVenta[[#This Row],[Ancho]],0)),"") | I19: =IF(ISNUMBER(H19),G19/H19,"") | J19: =IF(ISNUMBER(G19),IF(OR(B19="Textil Backlight",B19="Caja + Backlight"),E19*F19*G19,F19*I19),0) -> 0 | K19: =IF(ISTEXT(C19),VLOOKUP(C19,$AC$5:$AE$234,3,FALSE),"")
A20: 11 | D20: =IF(ISTEXT(C20),VLOOKUP(C20,$AC$5:$AE$234,2,FALSE),"") | H20: =IF(ISNUMBER(E20),IF(ROUNDDOWN(D20/E20,0)<1,NotaDeVenta[[#This Row],[Ancho Tela]]/NotaDeVenta[[#This Row],[Ancho]],ROUND(NotaDeVenta[[#This Row],[Ancho Tela]]/NotaDeVenta[[#This Row],[Ancho]],0)),"") | I20: =IF(ISNUMBER(H20),G20/H20,"") | J20: =IF(ISNUMBER(G20),IF(OR(B20="Textil Backlight",B20="Caja + Backlight"),E20*F20*G20,F20*I20),0) -> 0 | K20: =IF(ISTEXT(C20),VLOOKUP(C20,$AC$5:$AE$234,3,FALSE),"")
A21: 12 | D21: =IF(ISTEXT(C21),VLOOKUP(C21,$AC$5:$AE$234,2,FALSE),"") | H21: =IF(ISNUMBER(E21),IF(ROUNDDOWN(D21/E21,0)<1,NotaDeVenta[[#This Row],[Ancho Tela]]/NotaDeVenta[[#This Row],[Ancho]],ROUND(NotaDeVenta[[#This Row],[Ancho Tela]]/NotaDeVenta[[#This Row],[Ancho]],0)),"") | I21: =IF(ISNUMBER(H21),G21/H21,"") | J21: =IF(ISNUMBER(G21),IF(OR(B21="Textil Backlight",B21="Caja + Backlight"),E21*F21*G21,F21*I21),0) -> 0 | K21: =IF(ISTEXT(C21),VLOOKUP(C21,$AC$5:$AE$234,3,FALSE),"")
A22: 13 | D22: =IF(ISTEXT(C22),VLOOKUP(C22,$AC$5:$AE$234,2,FALSE),"") | H22: =IF(ISNUMBER(E22),IF(ROUNDDOWN(D22/E22,0)<1,NotaDeVenta[[#This Row],[Ancho Tela]]/NotaDeVenta[[#This Row],[Ancho]],ROUND(NotaDeVenta[[#This Row],[Ancho Tela]]/NotaDeVenta[[#This Row],[Ancho]],0)),"") | I22: =IF(ISNUMBER(H22),G22/H22,"") | J22: =IF(ISNUMBER(G22),IF(OR(B22="Textil Backlight",B22="Caja + Backlight"),E22*F22*G22,F22*I22),0) -> 0 | K22: =IF(ISTEXT(C22),VLOOKUP(C22,$AC$5:$AE$234,3,FALSE),"")
... A102: 93 | D102: =IF(ISTEXT(C102),VLOOKUP(C102,$AC$5:$AE$234,2,FALSE),"") | H102: =IF(ISNUMBER(E102),IF(ROUNDDOWN(D102/E102,0)<1,NotaDeVenta[[#This Row],[Ancho Tela]]/NotaDeVenta[[#This Row],[Ancho]],ROUND(NotaDeVenta[[#This Row],[Ancho Tela]]/NotaDeVenta[[#This Row],[Ancho]],0)),"") | I102: =IF(ISNUMBER(H102),G102/H102,"") | J102: =IF(ISNUMBER(G102),IF(OR(B102="Textil Backlight",B102="Caja + Backlight"),E102*F102*G102,F102*I102),0) -> 0 | K102: =IF(ISTEXT(C102),VLOOKUP(C102,$AC$5:$AE$234,3,FALSE),"")
A103: 94 | D103: =IF(ISTEXT(C103),VLOOKUP(C103,$AC$5:$AE$234,2,FALSE),"") | H103: =IF(ISNUMBER(E103),IF(ROUNDDOWN(D103/E103,0)<1,NotaDeVenta[[#This Row],[Ancho Tela]]/NotaDeVenta[[#This Row],[Ancho]],ROUND(NotaDeVenta[[#This Row],[Ancho Tela]]/NotaDeVenta[[#This Row],[Ancho]],0)),"") | I103: =IF(ISNUMBER(H103),G103/H103,"") | J103: =IF(ISNUMBER(G103),IF(OR(B103="Textil Backlight",B103="Caja + Backlight"),E103*F103*G103,F103*I103),0) -> 0 | K103: =IF(ISTEXT(C103),VLOOKUP(C103,$AC$5:$AE$234,3,FALSE),"") | Z103: base suelo plástico | AC103: Blackout | AD103: 1.48 | AE103: 12000 | AJ103: base suelo plástico | AK103: 25000 | AQ103: Base suelo metal más accesorio para rellenar
A104: 95 | D104: =IF(ISTEXT(C104),VLOOKUP(C104,$AC$5:$AE$234,2,FALSE),"") | H104: =IF(ISNUMBER(E104),IF(ROUNDDOWN(D104/E104,0)<1,NotaDeVenta[[#This Row],[Ancho Tela]]/NotaDeVenta[[#This Row],[Ancho]],ROUND(NotaDeVenta[[#This Row],[Ancho Tela]]/NotaDeVenta[[#This Row],[Ancho]],0)),"") | I104: =IF(ISNUMBER(H104),G104/H104,"") | J104: =IF(ISNUMBER(G104),IF(OR(B104="Textil Backlight",B104="Caja + Backlight"),E104*F104*G104,F104*I104),0) -> 0 | K104: =IF(ISTEXT(C104),VLOOKUP(C104,$AC$5:$AE$234,3,FALSE),"") | Z104: Camino de mesa | AC104: Canvas tarpaulin | AD104: 1.48 | AE104: 11000 | AJ104: Camino de mesa | AK104: 5000 | AQ104: Base suelo plástico para rellenar
A105: 96 | D105: =IF(ISTEXT(C105),VLOOKUP(C105,$AC$5:$AE$234,2,FALSE),"") | H105: =IF(ISNUMBER(E105),IF(ROUNDDOWN(D105/E105,0)<1,NotaDeVenta[[#This Row],[Ancho Tela]]/NotaDeVenta[[#This Row],[Ancho]],ROUND(NotaDeVenta[[#This Row],[Ancho Tela]]/NotaDeVenta[[#This Row],[Ancho]],0)),"") | I105: =IF(ISNUMBER(H105),G105/H105,"") | J105: =IF(ISNUMBER(G105),IF(OR(B105="Textil Backlight",B105="Caja + Backlight"),E105*F105*G105,F105*I105),0) -> 0 | K105: =IF(ISTEXT(C105),VLOOKUP(C105,$AC$5:$AE$234,3,FALSE),"") | Z105: cubre sensor | AC105: Crea sábana algodón | AD105: 1.48 | AE105: 11000 | AJ105: cubre sensor | AK105: 3500 | AQ105: Bolso de transporte con ruedas 1 estructura panel araña
A106: 97 | D106: =IF(ISTEXT(C106),VLOOKUP(C106,$AC$5:$AE$234,2,FALSE),"") | H106: =IF(ISNUMBER(E106),IF(ROUNDDOWN(D106/E106,0)<1,NotaDeVenta[[#This Row],[Ancho Tela]]/NotaDeVenta[[#This Row],[Ancho]],ROUND(NotaDeVenta[[#This Row],[Ancho Tela]]/NotaDeVenta[[#This Row],[Ancho]],0)),"") | I106: =IF(ISNUMBER(H106),G106/H106,"") | J106: =IF(ISNUMBER(G106),IF(OR(B106="Textil Backlight",B106="Caja + Backlight"),E106*F106*G106,F106*I106),0) -> 0 | K106: =IF(ISTEXT(C106),VLOOKUP(C106,$AC$5:$AE$234,3,FALSE),"") | Z106: estaca | AC106: Crea sábana poliester | AD106: 1.38 | AE106: 10000 | AJ106: estaca | AK106: 10000 | AQ106: Bolso de transporte con ruedas 2 estructuras panel araña
A107: 98 | D107: =IF(ISTEXT(C107),VLOOKUP(C107,$AC$5:$AE$234,2,FALSE),"") | H107: =IF(ISNUMBER(E107),IF(ROUNDDOWN(D107/E107,0)<1,NotaDeVenta[[#This Row],[Ancho Tela]]/NotaDeVenta[[#This Row],[Ancho]],ROUND(NotaDeVenta[[#This Row],[Ancho Tela]]/NotaDeVenta[[#This Row],[Ancho]],0)),"") | I107: =IF(ISNUMBER(H107),G107/H107,"") | J107: =IF(ISNUMBER(G107),IF(OR(B107="Textil Backlight",B107="Caja + Backlight"),E107*F107*G107,F107*I107),0) -> 0 | K107: =IF(ISTEXT(C107),VLOOKUP(C107,$AC$5:$AE$234,3,FALSE),"") | Z107: estampado textil sin terminaciones | AC107: Cuerina | AD107: 1.38 | AE107: 12000 | AJ107: estampado textil sin terminaciones | AK107: 2000 | AQ107: Cosmetiquero 20x30 cms 1 cara
A108: 99 | D108: =IF(ISTEXT(C108),VLOOKUP(C108,$AC$5:$AE$234,2,FALSE),"") | H108: =IF(ISNUMBER(E108),IF(ROUNDDOWN(D108/E108,0)<1,NotaDeVenta[[#This Row],[Ancho Tela]]/NotaDeVenta[[#This Row],[Ancho]],ROUND(NotaDeVenta[[#This Row],[Ancho Tela]]/NotaDeVenta[[#This Row],[Ancho]],0)),"") | I108: =IF(ISNUMBER(H108),G108/H108,"") | J108: =IF(ISNUMBER(G108),IF(OR(B108="Textil Backlight",B108="Caja + Backlight"),E108*F108*G108,F108*I108),0) -> 0 | K108: =IF(ISTEXT(C108),VLOOKUP(C108,$AC$5:$AE$234,3,FALSE),"")
A109: 100 | D109: =IF(ISTEXT(C109),VLOOKUP(C109,$AC$5:$AE$234,2,FALSE),"") | H109: =IF(ISNUMBER(E109),IF(ROUNDDOWN(D109/E109,0)<1,NotaDeVenta[[#This Row],[Ancho Tela]]/NotaDeVenta[[#This Row],[Ancho]],ROUND(NotaDeVenta[[#This Row],[Ancho Tela]]/NotaDeVenta[[#This Row],[Ancho]],0)),"") | I109: =IF(ISNUMBER(H109),G109/H109,"") | J109: =IF(ISNUMBER(G109),IF(OR(B109="Textil Backlight",B109="Caja + Backlight"),E109*F109*G109,F109*I109),0) -> 0 | K109: =IF(ISTEXT(C109),VLOOKUP(C109,$AC$5:$AE$234,3,FALSE),"")
A110: 101 | D110: =IF(ISTEXT(C110),VLOOKUP(C110,$AC$5:$AE$234,2,FALSE),"") | H110: =IF(ISNUMBER(E110),IF(ROUNDDOWN(D110/E110,0)<1,NotaDeVenta[[#This Row],[Ancho Tela]]/NotaDeVenta[[#This Row],[Ancho]],ROUND(NotaDeVenta[[#This Row],[Ancho Tela]]/NotaDeVenta[[#This Row],[Ancho]],0)),"") | I110: =IF(ISNUMBER(H110),G110/H110,"") | J110: =IF(ISNUMBER(G110),IF(OR(B110="Textil Backlight",B110="Caja + Backlight"),E110*F110*G110,F110*I110),0) -> 0 | K110: =IF(ISTEXT(C110),VLOOKUP(C110,$AC$5:$AE$234,3,FALSE),"") | Z110: Estuches | AC110: Felpa gruesa | AD110: 1.38 | AE110: 12000 | AJ110: Estuches | AK110: 3000 | AQ110: Cubre alarma
G111: =IF(ISNUMBER(G10),SUM(G10:G110),"") | J111: =IF(ISNUMBER(J10),SUM(J10:J110),"") -> 0 | Z111: fleje arriba y abajo | AC111: Franela | AD111: 1.48 | AE111: 12000 | AJ111: fleje arriba y abajo | AK111: 10500 | AQ111: Estaca
B112: Nombre del Trabajo
B113: Descripcion del producto | Z113: Funda Almohada | AC113: Gabardina antiflu | AD113: 1.48 | AE113: 12000 | AJ113: Funda Almohada | AK113: 6000 | AQ113: Estuche 18x23 cms 1 cara
B114: observaciones produccion | Z114: Funda Cojín | AC114: Gasa | AD114: 1.46 | AE114: 12000 | AJ114: Funda Cojín | AK114: 4000 | AQ114: Estuche 18x23 cms tiro y retiro
Z115: lienzo simple con bolsillo SIN estructuras | AC115: Gasa rustica | AD115: 1.38 | AE115: 12800 | AJ115: lienzo simple con bolsillo SIN estructuras | AK115: 7000 | AQ115: Estuche lapicero 5x20 cms
B116: Producto | C116: Valor impresion total | D116: Estructura | E116: Terminaciones | F116: Otros x1 | G116: Valor unitario prod | H116: Total neto | I116: Valor Impresión Unit | Z116: lienzo simple con bolsillos, estructutras, accesorios para colgar | AC116: Hole | AD116: 1.58 | AE116: 8000 | AJ116: lienzo simple con bolsillos, estructutras, accesorios para colgar | AK116: 10000 | AQ116: Estuches lentes 22x12 cms tiro y retiro
A117: 1 | B117: =B10 -> 0 | C117: =IF(ISNUMBER(K10),J10*K10,0) -> 0 | D117: =IF(ISNUMBER(C117),VLOOKUP(B117,Productos!$A$2:$G$111,7,FALSE),0) -> #N/A | E117: =IF(B117<>"",VLOOKUP(B117,Productos!$A$2:$G$116,6,FALSE),0) -> #N/A | G117: =IF(B117="Caja + Backlight",'NV CAJAS (BL)'!L27+TablaValoresProducto[[#This Row],[Valor Impresión Unit]]+TablaValoresProducto[[#This Row],[Estructura]]+TablaValoresProducto[[#This Row],[Terminaciones]]+TablaValoresProducto[[#This Row],[Otros x1]],IF(ISNUMBER(TablaValoresProducto[[#This Row],[Valor impresion total]]),TablaValoresProducto[[#This Row],[Valor impresion total]]/G10+TablaValoresProducto[[#This Row],[Estructura]]+TablaValoresProducto[[#This Row],[Terminaciones]]+TablaValoresProducto[[#This Row],[Otros x1]],0)) -> #DIV/0! | H117: =IF(ISNUMBER(G117),G117*G10,0) -> 0 | I117: =TablaValoresProducto[[#This Row],[Valor impresion total]]/G10 -> #DIV/0! | Z117: lienzo tiro y retiro con bolsillos SIN estructuras | AC117: Jersey | AD117: 1.48 | AE117: 10500 | AJ117: lienzo tiro y retiro con bolsillos SIN estructuras | AK117: 15000 | AQ117: Forro textil soporte muro 2,3x2,3 mts tiro y retiro
A118: 2 | B118: =B11 -> 0 | C118: =IF(ISNUMBER(K11),J11*K11,0) -> 0 | D118: =IF(ISNUMBER(C118),VLOOKUP(B118,Productos!$A$2:$G$111,7,FALSE),0) -> #N/A | E118: =IF(B118<>"",VLOOKUP(B118,Productos!$A$2:$G$116,6,FALSE),0) -> #N/A | G118: =IF(B118="Caja + Backlight",'NV CAJAS (BL)'!L28+TablaValoresProducto[[#This Row],[Valor Impresión Unit]]+TablaValoresProducto[[#This Row],[Estructura]]+TablaValoresProducto[[#This Row],[Terminaciones]]+TablaValoresProducto[[#This Row],[Otros x1]],IF(ISNUMBER(TablaValoresProducto[[#This Row],[Valor impresion total]]),TablaValoresProducto[[#This Row],[Valor impresion total]]/G11+TablaValoresProducto[[#This Row],[Estructura]]+TablaValoresProducto[[#This Row],[Terminaciones]]+TablaValoresProducto[[#This Row],[Otros x1]],0)) -> #DIV/0! | H118: =IF(ISNUMBER(G118),G118*G11,0) -> 0 | I118: =TablaValoresProducto[[#This Row],[Valor impresion total]]/G11 -> #DIV/0!
A119: 3 | B119: =B12 -> 0 | C119: =IF(ISNUMBER(K12),J12*K12,0) -> 0 | D119: =IF(ISNUMBER(C119),VLOOKUP(B119,Productos!$A$2:$G$111,7,FALSE),0) -> #N/A | E119: =IF(B119<>"",VLOOKUP(B119,Productos!$A$2:$G$116,6,FALSE),0) -> #N/A | G119: =IF(B119="Caja + Backlight",'NV CAJAS (BL)'!L29+TablaValoresProducto[[#This Row],[Valor Impresión Unit]]+TablaValoresProducto[[#This Row],[Estructura]]+TablaValoresProducto[[#This Row],[Terminaciones]]+TablaValoresProducto[[#This Row],[Otros x1]],IF(ISNUMBER(TablaValoresProducto[[#This Row],[Valor impresion total]]),TablaValoresProducto[[#This Row],[Valor impresion total]]/G12+TablaValoresProducto[[#This Row],[Estructura]]+TablaValoresProducto[[#This Row],[Terminaciones]]+TablaValoresProducto[[#This Row],[Otros x1]],0)) -> #DIV/0! | H119: =IF(ISNUMBER(G119),G119*G12,0) -> 0 | I119: =TablaValoresProducto[[#This Row],[Valor impresion total]]/G12 -> #DIV/0!
A120: 4 | B120: =B13 -> 0 | C120: =IF(ISNUMBER(K13),J13*K13,0) -> 0 | D120: =IF(ISNUMBER(C120),VLOOKUP(B120,Productos!$A$2:$G$111,7,FALSE),0) -> #N/A | E120: =IF(B120<>"",VLOOKUP(B120,Productos!$A$2:$G$116,6,FALSE),0) -> #N/A | G120: =IF(B120="Caja + Backlight",'NV CAJAS (BL)'!L30+TablaValoresProducto[[#This Row],[Valor Impresión Unit]]+TablaValoresProducto[[#This Row],[Estructura]]+TablaValoresProducto[[#This Row],[Terminaciones]]+TablaValoresProducto[[#This Row],[Otros x1]],IF(ISNUMBER(TablaValoresProducto[[#This Row],[Valor impresion total]]),TablaValoresProducto[[#This Row],[Valor impresion total]]/G13+TablaValoresProducto[[#This Row],[Estructura]]+TablaValoresProducto[[#This Row],[Terminaciones]]+TablaValoresProducto[[#This Row],[Otros x1]],0)) -> #DIV/0! | H120: =IF(ISNUMBER(G120),G120*G13,0) -> 0 | I120: =TablaValoresProducto[[#This Row],[Valor impresion total]]/G13 -> #DIV/0!
A121: 5 | B121: =B14 -> 0 | C121: =IF(ISNUMBER(K14),J14*K14,0) -> 0 | D121: =IF(ISNUMBER(C121),VLOOKUP(B121,Productos!$A$2:$G$111,7,FALSE),0) -> #N/A | E121: =IF(B121<>"",VLOOKUP(B121,Productos!$A$2:$G$116,6,FALSE),0) -> #N/A | G121: =IF(B121="Caja + Backlight",'NV CAJAS (BL)'!L31+TablaValoresProducto[[#This Row],[Valor Impresión Unit]]+TablaValoresProducto[[#This Row],[Estructura]]+TablaValoresProducto[[#This Row],[Terminaciones]]+TablaValoresProducto[[#This Row],[Otros x1]],IF(ISNUMBER(TablaValoresProducto[[#This Row],[Valor impresion total]]),TablaValoresProducto[[#This Row],[Valor impresion total]]/G14+TablaValoresProducto[[#This Row],[Estructura]]+TablaValoresProducto[[#This Row],[Terminaciones]]+TablaValoresProducto[[#This Row],[Otros x1]],0)) -> #DIV/0! | H121: =IF(ISNUMBER(G121),G121*G14,0) -> 0 | I121: =TablaValoresProducto[[#This Row],[Valor impresion total]]/G14 -> #DIV/0!
...

Sheet Cotización
H1: COTIZACIÓN Nº: | I1: ='Nota de venta'!H1 -> 0 | AD1: Venta Directa | AG1: RC Ferias | AJ1: Inser
Y2: E-Mail | Z2: Sí | AA2: Directo | AB2: Tela | AC2: Valor Mínimo | AD2: 3-50 m2 | AE2: 51-100 m2 | AF2: 101-200 m2 | AG2: 3-50 m2 | AH2: 51-100 m2 | AI2: 101-200 m2 | AJ2: 3-100 m2 | AK2: 101-300 m2 | AL2: Pop Up
B3: fecha | C3: ='Nota de venta'!C2 -> 0 | Y3: CD/DVD | Z3: No | AA3: RC Ferias | AB3: 3304 - Bandera | AC3: 35000 | AD3: 14000 | AE3: 12500 | AF3: 10500 | AG3: 11000 | AH3: 9500 | AI3: 8000 | AJ3: 9500 | AK3: 8000 | AL3: Roller
B4: DATOS CLIENTE | Y4: Laser | AA4: Inser | AB4: 3306 - Mesh Mate | AC4: 36000 | AD4: 15000 | AE4: 13000 | AF4: 11500 | AG4: 11500 | AH4: 10000 | AI4: 9000 | AJ4: 10000 | AK4: 9000 | AL4: Pendón
B5: Estimado(a): | C5: ='Nota de venta'!C5 -> 0 | F5: Rut: | H5: ='Nota de venta'!I6 -> 0 | Y5: Otros | AB5: 3307 - Mesh Brillante | AC5: 36000 | AD5: 15000 | AE5: 13000 | AF5: 11500 | AG5: 11500 | AH5: 10000 | AI5: 9000 | AJ5: 10000 | AK5: 9000 | AL5: Bandera
B6: Empresa: | C6: ='Nota de venta'!C6 -> 0 | F6: Razon Social: | H6: ='Nota de venta'!I5 -> 0 | AB6: 3302 - Satín | AC6: 40000 | AD6: 15500 | AE6: 13500 | AF6: 12000 | AG6: 12000 | AH6: 11000 | AI6: 10000 | AJ6: 11000 | AK6: 10000 | AL6: Panel
B7: Nombre: | C7: ='Nota de venta'!C112 -> 0 | F7: Condiciones de pago: | AB7: 3308 - Perforado | AC7: 40000 | AD7: 16000 | AE7: 14000 | AF7: 12500 | AG7: 12500 | AH7: 11500 | AI7: 10500 | AJ7: 11500 | AK7: 10500 | AL7: Otros
B8: Descripción: | C8: ='Nota de venta'!C113 -> 0
B10: REQUERIMIENTO TEXTIL | N10: =#REF! -> #REF! | AB10: 3309 - Canvas | AC10: 40000 | AD10: 16500 | AE10: 14500 | AF10: 13000 | AG10: 13000 | AH10: 12000 | AI10: 11000 | AJ10: 12000 | AK10: 11000
B11: Tema | C11: # | D11: Producto | E11: Ancho | F11: Alto | G11: ML | H11: valor unitario | I11: Valor Total | X11: 3340 - Popelina | Y11: 45000 | Z11: 17000 | AA11: 15000 | AB11: 14000 | AC11: 14000 | AD11: 13000 | AE11: 12000 | AF11: 13000 | AG11: 12000
A12: 1 | B12: ='Nota de venta'!L10 -> Tema | C12: ='Nota de venta'!G10 -> 0 | D12: ='Nota de venta'!B10 -> 0 | E12: ='Nota de venta'!E10 -> 0 | F12: ='Nota de venta'!F10 -> 0 | G12: ='Nota de venta'!J10 -> 0 | H12: ='Nota de venta'!G117 -> #DIV/0! | I12: =IF(ISNUMBER(COTIZACION[[#This Row],[valor unitario]]),COTIZACION[[#This Row],[valor unitario]]*COTIZACION[[#This Row],['#]],0) -> 0
A13: 2 | B13: ='Nota de venta'!L11 -> 0 | C13: ='Nota de venta'!G11 -> 0 | D13: ='Nota de venta'!B11 -> 0 | E13: ='Nota de venta'!E11 -> 0 | F13: ='Nota de venta'!F11 -> 0 | G13: ='Nota de venta'!J11 -> 0 | H13: ='Nota de venta'!G118 -> #DIV/0! | I13: =IF(ISNUMBER(COTIZACION[[#This Row],[valor unitario]]),COTIZACION[[#This Row],[valor unitario]]*COTIZACION[[#This Row],['#]],0) -> 0
A14: 3 | B14: ='Nota de venta'!L12 -> 0 | C14: ='Nota de venta'!G12 -> 0 | D14: ='Nota de venta'!B12 -> 0 | E14: ='Nota de venta'!E12 -> 0 | F14: ='Nota de venta'!F12 -> 0 | G14: ='Nota de venta'!J12 -> 0 | H14: ='Nota de venta'!G119 -> #DIV/0! | I14: =IF(ISNUMBER(COTIZACION[[#This Row],[valor unitario]]),COTIZACION[[#This Row],[valor unitario]]*COTIZACION[[#This Row],['#]],0) -> 0
A15: 4 | B15: ='Nota de venta'!L13 -> 0 | C15: ='Nota de venta'!G13 -> 0 | D15: ='Nota de venta'!B13 -> 0 | E15: ='Nota de venta'!E13 -> 0 | F15: ='Nota de venta'!F13 -> 0 | G15: ='Nota de venta'!J13 -> 0 | H15: ='Nota de venta'!G120 -> #DIV/0! | I15: =IF(ISNUMBER(COTIZACION[[#This Row],[valor unitario]]),COTIZACION[[#This Row],[valor unitario]]*COTIZACION[[#This Row],['#]],0) -> 0
A16: 5 | B16: ='Nota de venta'!L14 -> 0 | C16: ='Nota de venta'!G14 -> 0 | D16: ='Nota de venta'!B14 -> 0 | E16: ='Nota de venta'!E14 -> 0 | F16: ='Nota de venta'!F14 -> 0 | G16: ='Nota de venta'!J14 -> 0 | H16: ='Nota de venta'!G121 -> #DIV/0! | I16: =IF(ISNUMBER(COTIZACION[[#This Row],[valor unitario]]),COTIZACION[[#This Row],[valor unitario]]*COTIZACION[[#This Row],['#]],0) -> 0
A17: 6 | B17: ='Nota de venta'!L15 -> 0 | C17: ='Nota de venta'!G15 -> 0 | D17: ='Nota de venta'!B15 -> 0 | E17: ='Nota de venta'!E15 -> 0 | F17: ='Nota de venta'!F15 -> 0 | G17: ='Nota de venta'!J15 -> 0 | H17: ='Nota de venta'!G122 -> #DIV/0! | I17: =IF(ISNUMBER(COTIZACION[[#This Row],[valor unitario]]),COTIZACION[[#This Row],[valor unitario]]*COTIZACION[[#This Row],['#]],0) -> 0
A18: 7 | B18: ='Nota de venta'!L16 -> 0 | C18: ='Nota de venta'!G16 -> 0 | D18: ='Nota de venta'!B16 -> 0 | E18: ='Nota de venta'!E16 -> 0 | F18: ='Nota de venta'!F16 -> 0 | G18: ='Nota de venta'!J16 -> 0 | H18: ='Nota de venta'!G123 -> #DIV/0! | I18: =IF(ISNUMBER(COTIZACION[[#This Row],[valor unitario]]),COTIZACION[[#This Row],[valor unitario]]*COTIZACION[[#This Row],['#]],0) -> 0
A19: 8 | B19: ='Nota de venta'!L17 -> 0 | C19: ='Nota de venta'!G17 -> 0 | D19: ='Nota de venta'!B17 -> 0 | E19: ='Nota de venta'!E17 -> 0 | F19: ='Nota de venta'!F17 -> 0 | G19: ='Nota de venta'!J17 -> 0 | H19: ='Nota de venta'!G124 -> #DIV/0! | I19: =IF(ISNUMBER(COTIZACION[[#This Row],[valor unitario]]),COTIZACION[[#This Row],[valor unitario]]*COTIZACION[[#This Row],['#]],0) -> 0
A20: 9 | B20: ='Nota de venta'!L18 -> 0 | C20: ='Nota de venta'!G18 -> 0 | D20: ='Nota de venta'!B18 -> 0 | E20: ='Nota de venta'!E18 -> 0 | F20: ='Nota de venta'!F18 -> 0 | G20: ='Nota de venta'!J18 -> 0 | H20: ='Nota de venta'!G125 -> #DIV/0! | I20: =IF(ISNUMBER(COTIZACION[[#This Row],[valor unitario]]),COTIZACION[[#This Row],[valor unitario]]*COTIZACION[[#This Row],['#]],0) -> 0
A21: 10 | B21: ='Nota de venta'!L19 -> 0 | C21: ='Nota de venta'!G19 -> 0 | D21: ='Nota de venta'!B19 -> 0 | E21: ='Nota de venta'!E19 -> 0 | F21: ='Nota de venta'!F19 -> 0 | G21: ='Nota de venta'!J19 -> 0 | H21: ='Nota de venta'!G126 -> #DIV/0! | I21: =IF(ISNUMBER(COTIZACION[[#This Row],[valor unitario]]),COTIZACION[[#This Row],[valor unitario]]*COTIZACION[[#This Row],['#]],0) -> 0
A22: 11 | B22: ='Nota de venta'!L20 -> 0 | C22: ='Nota de venta'!G20 -> 0 | D22: ='Nota de venta'!B20 -> 0 | E22: ='Nota de venta'!E20 -> 0 | F22: ='Nota de venta'!F20 -> 0 | G22: ='Nota de venta'!J20 -> 0 | H22: ='Nota de venta'!G127 -> #DIV/0! | I22: =IF(ISNUMBER(COTIZACION[[#This Row],[valor unitario]]),COTIZACION[[#This Row],[valor unitario]]*COTIZACION[[#This Row],['#]],0) -> 0
A23: 12 | B23: ='Nota de venta'!L21 -> 0 | C23: ='Nota de venta'!G21 -> 0 | D23: ='Nota de venta'!B21 -> 0 | E23: ='Nota de venta'!E21 -> 0 | F23: ='Nota de venta'!F21 -> 0 | G23: ='Nota de venta'!J21 -> 0 | H23: ='Nota de venta'!G128 -> #DIV/0! | I23: =IF(ISNUMBER(COTIZACION[[#This Row],[valor unitario]]),COTIZACION[[#This Row],[valor unitario]]*COTIZACION[[#This Row],['#]],0) -> 0
... A110: 99 | B110: ='Nota de venta'!L108 -> 0 | C110: ='Nota de venta'!G108 -> 0 | D110: ='Nota de venta'!B108 -> 0 | E110: ='Nota de venta'!E108 -> 0 | F110: ='Nota de venta'!F108 -> 0 | G110: ='Nota de venta'!J108 -> 0 | H110: ='Nota de venta'!G215 -> #DIV/0! | I110: =IF(ISNUMBER(COTIZACION[[#This Row],[valor unitario]]),COTIZACION[[#This Row],[valor unitario]]*COTIZACION[[#This Row],['#]],0) -> 0
A111: 100 | B111: ='Nota de venta'!L109 -> 0 | C111: ='Nota de venta'!G109 -> 0 | D111: ='Nota de venta'!B109 -> 0 | E111: ='Nota de venta'!E110 -> 0 | F111: ='Nota de venta'!F110 -> 0 | G111: ='Nota de venta'!J110 -> 0 | H111: ='Nota de venta'!G216 -> #DIV/0! | I111: =IF(ISNUMBER(COTIZACION[[#This Row],[valor unitario]]),COTIZACION[[#This Row],[valor unitario]]*COTIZACION[[#This Row],['#]],0) -> 0
C112: =SUM(COTIZACION['#]) -> 0 | H112: neto | I112: =SUM(I12:I111) -> 0
B113: Dias hábiles de producción con VºBº aprobado: | H113: descto aplicado | I113: {=IF('Nota de venta'!I7:J7*SUM('Nota de venta'!H117:H216)>'Nota de venta'!AO217,'Nota de venta'!I7:J7*SUM('Nota de venta'!H117:H216),'Nota de venta'!AO217)} -> 0 | J113: 0
H114: neto total | I114: =+I112-I113 -> 0
H115: iva | I115: =+I114*0.19 -> 0
H116: total | I116: =+I114+I115 -> 0
B117: Los valores dados en esta cotización son válidos para las cantidades aquí mencionadas. Cambios en cantidades deben ser recotizados.
B120: Si esta cotización es aprobada, devuélvala firmada por E-Mail o adjunte su Orden de Compra a: admin@texdigital.cl
B122: Datos para OC: | C122: Textiles Digitales Ltda./ 76.144.885-4/Ss. De Publicidad/ San Isidro 1927/ Santiago/Chile
B124: Datos bancarios: | D124: BANCO SANTANDER.CTA CTE: 0-000-8759710-5

Sheet OP
I1: Nº OP | J1: ='Nota de venta'!H1 -> 0
D2: ='Nota de venta'!C112 -> 0
I3: Ingreso
I4: Entrega
A5: cliente | B5: ='Nota de venta'!C6 -> 0 | I5: contacto | J5: ='Nota de venta'!C5 -> 0
A7: OBSERVACION | B7: ='Nota de venta'!C114 -> 0
AM8: Inser
A9: TEMA | B9: Producto | C9: Textil | D9: Ancho | E9: Alto | F9: # | G9: ML | H9: obs
A10: =NotaDeVenta[[#This Row],[Tema]] -> Tema | B10: =NotaDeVenta[[#This Row],[Producto]] -> 0 | C10: =NotaDeVenta[[#This Row],[Textil]] -> 0 | D10: =NotaDeVenta[[#This Row],[Ancho]] -> 0 | E10: =NotaDeVenta[[#This Row],[Alto]] -> 0 | F10: =NotaDeVenta[[#This Row],[Cantidad]] -> 0 | G10: =NotaDeVenta[[#This Row],[ML impresos]] -> 0
A11: =NotaDeVenta[[#This Row],[Tema]] -> 0 | B11: =NotaDeVenta[[#This Row],[Producto]] -> 0 | C11: =NotaDeVenta[[#This Row],[Textil]] -> 0 | D11: =NotaDeVenta[[#This Row],[Ancho]] -> 0 | E11: =NotaDeVenta[[#This Row],[Alto]] -> 0 | F11: =NotaDeVenta[[#This Row],[Cantidad]] -> 0 | G11: =NotaDeVenta[[#This Row],[ML impresos]] -> 0
A12: =NotaDeVenta[[#This Row],[Tema]] -> 0 | B12: =NotaDeVenta[[#This Row],[Producto]] -> 0 | C12: =NotaDeVenta[[#This Row],[Textil]] -> 0 | D12: =NotaDeVenta[[#This Row],[Ancho]] -> 0 | E12: =NotaDeVenta[[#This Row],[Alto]] -> 0 | F12: =NotaDeVenta[[#This Row],[Cantidad]] -> 0 | G12: =NotaDeVenta[[#This Row],[ML impresos]] -> 0
A13: =NotaDeVenta[[#This Row],[Tema]] -> 0 | B13: =NotaDeVenta[[#This Row],[Producto]] -> 0 | C13: =NotaDeVenta[[#This Row],[Textil]] -> 0 | D13: =NotaDeVenta[[#This Row],[Ancho]] -> 0 | E13: =NotaDeVenta[[#This Row],[Alto]] -> 0 | F13: =NotaDeVenta[[#This Row],[Cantidad]] -> 0 | G13: =NotaDeVenta[[#This Row],[ML impresos]] -> 0
A14: =NotaDeVenta[[#This Row],[Tema]] -> 0 | B14: =NotaDeVenta[[#This Row],[Producto]] -> 0 | C14: =NotaDeVenta[[#This Row],[Textil]] -> 0 | D14: =NotaDeVenta[[#This Row],[Ancho]] -> 0 | E14: =NotaDeVenta[[#This Row],[Alto]] -> 0 | F14: =NotaDeVenta[[#This Row],[Cantidad]] -> 0 | G14: =NotaDeVenta[[#This Row],[ML impresos]] -> 0
A15: =NotaDeVenta[[#This Row],[Tema]] -> 0 | B15: =NotaDeVenta[[#This Row],[Producto]] -> 0 | C15: =NotaDeVenta[[#This Row],[Textil]] -> 0 | D15: =NotaDeVenta[[#This Row],[Ancho]] -> 0 | E15: =NotaDeVenta[[#This Row],[Alto]] -> 0 | F15: =NotaDeVenta[[#This Row],[Cantidad]] -> 0 | G15: =NotaDeVenta[[#This Row],[ML impresos]] -> 0
A16: =NotaDeVenta[[#This Row],[Tema]] -> 0 | B16: =NotaDeVenta[[#This Row],[Producto]] -> 0 | C16: =NotaDeVenta[[#This Row],[Textil]] -> 0 | D16: =NotaDeVenta[[#This Row],[Ancho]] -> 0 | E16: =NotaDeVenta[[#This Row],[Alto]] -> 0 | F16: =NotaDeVenta[[#This Row],[Cantidad]] -> 0 | G16: =NotaDeVenta[[#This Row],[ML impresos]] -> 0
A17: =NotaDeVenta[[#This Row],[Tema]] -> 0 | B17: =NotaDeVenta[[#This Row],[Producto]] -> 0 | C17: =NotaDeVenta[[#This Row],[Textil]] -> 0 | D17: =NotaDeVenta[[#This Row],[Ancho]] -> 0 | E17: =NotaDeVenta[[#This Row],[Alto]] -> 0 | F17: =NotaDeVenta[[#This Row],[Cantidad]] -> 0 | G17: =NotaDeVenta[[#This Row],[ML impresos]] -> 0
A18: =NotaDeVenta[[#This Row],[Tema]] -> 0 | B18: =NotaDeVenta[[#This Row],[Producto]] -> 0 | C18: =NotaDeVenta[[#This Row],[Textil]] -> 0 | D18: =NotaDeVenta[[#This Row],[Ancho]] -> 0 | E18: =NotaDeVenta[[#This Row],[Alto]] -> 0 | F18: =NotaDeVenta[[#This Row],[Cantidad]] -> 0 | G18: =NotaDeVenta[[#This Row],[ML impresos]] -> 0
A19: =NotaDeVenta[[#This Row],[Tema]] -> 0 | B19: =NotaDeVenta[[#This Row],[Producto]] -> 0 | C19: =NotaDeVenta[[#This Row],[Textil]] -> 0 | D19: =NotaDeVenta[[#This Row],[Ancho]] -> 0 | E19: =NotaDeVenta[[#This Row],[Alto]] -> 0 | F19: =NotaDeVenta[[#This Row],[Cantidad]] -> 0 | G19: =NotaDeVenta[[#This Row],[ML impresos]] -> 0
A20: =NotaDeVenta[[#This Row],[Tema]] -> 0 | B20: =NotaDeVenta[[#This Row],[Producto]] -> 0 | C20: =NotaDeVenta[[#This Row],[Textil]] -> 0 | D20: =NotaDeVenta[[#This Row],[Ancho]] -> 0 | E20: =NotaDeVenta[[#This Row],[Alto]] -> 0 | F20: =NotaDeVenta[[#This Row],[Cantidad]] -> 0 | G20: =NotaDeVenta[[#This Row],[ML impresos]] -> 0
A21: =NotaDeVenta[[#This Row],[Tema]] -> 0 | B21: =NotaDeVenta[[#This Row],[Producto]] -> 0 | C21: =NotaDeVenta[[#This Row],[Textil]] -> 0 | D21: =NotaDeVenta[[#This Row],[Ancho]] -> 0 | E21: =NotaDeVenta[[#This Row],[Alto]] -> 0 | F21: =NotaDeVenta[[#This Row],[Cantidad]] -> 0 | G21: =NotaDeVenta[[#This Row],[ML impresos]] -> 0
... A110: =NotaDeVenta[[#This Row],[Tema]] -> 0 | B110: =NotaDeVenta[[#This Row],[Producto]] -> 0 | C110: =NotaDeVenta[[#This Row],[Textil]] -> 0 | D110: =NotaDeVenta[[#This Row],[Ancho]] -> 0 | E110: =NotaDeVenta[[#This Row],[Alto]] -> 0 | F110: =NotaDeVenta[[#This Row],[Cantidad]] -> 0 | G110: =NotaDeVenta[[#This Row],[ML impresos]] -> 0
F111: =SUM(F10:F110) -> 0 | G111: =SUM(G10:G110) -> 0 | AM111: vehículo propio
A113: MTS TOTALES PAPEL | H113: PRENSA:
A114: MTS TOTALES TELA | E114: Nº ROLLO
A115: CONFECCIÓN:
A116: DESPACHO

Sheet OP TELAS
I1: Nº OP | J1: ='Nota de venta'!H1 -> 0 | Z1: CAJA TERMINADA | AA1: Tela
D2: ='Nota de venta'!C112 -> 0 | Z2: AREA VISUAL | AA2: popelina backlight 155
I3: Ingreso | AA3: popelina backlight 310
I4: Entrega | AA4: pearl 155
B5: cliente | C5: ='Nota de venta'!C6 -> 0 | AA5: pearl 310
B6: obs: | C6: ='Nota de venta'!C114 -> 0 | I6: valor impresión | AA6: pearl 160 hp
J7: CAJA TERMINADA
B8: textil | C8: # | D8: ANCHO | E8: ALTO | F8: exc cms x lado | G8: ancho final | H8: alto final | I8: m2 unit | J8: m2 total | K8: valor unit | L8: corte ancho | M8: corte alto | N8: tema
A9: 1 | B9: ='Nota de venta'!C10 -> 0 | C9: ='Nota de venta'!G10 -> 0 | D9: ='Nota de venta'!E10 -> 0 | E9: ='Nota de venta'!F10 -> 0 | F9: 1.5 | G9: =TablaOpTelas[[#This Row],[ANCHO]]+(TablaOpTelas[[#This Row],[exc cms x lado]]/100)*2 -> 0.03 | H9: =TablaOpTelas[[#This Row],[ALTO]]+(TablaOpTelas[[#This Row],[exc cms x lado]]/100)*2 -> 0.03 | I9: =TablaOpTelas[[#This Row],[ancho final]]*TablaOpTelas[[#This Row],[alto final]] -> 0.0009 | J9: =TablaOpTelas[[#This Row],[m2 unit]]*TablaOpTelas[[#This Row],['#]] -> 0 | K9: =TablaOpTelas[[#This Row],[ANCHO]]*TablaOpTelas[[#This Row],[ALTO]]*$J$6 -> 0 | L9: =IF($J$7="CAJA TERMINADA",TablaOpTelas[[#This Row],[ANCHO]]+0.013,TablaOpTelas[[#This Row],[ANCHO]]+0.023) -> 0.013 | M9: =IF($J$7="CAJA TERMINADA",TablaOpTelas[[#This Row],[ALTO]]+0.013,TablaOpTelas[[#This Row],[ALTO]]+0.023) -> 0.013 | N9: ='Nota de venta'!L10 -> Tema
A10: 2 | B10: ='Nota de venta'!C11 -> 0 | C10: ='Nota de venta'!G11 -> 0 | D10: ='Nota de venta'!E11 -> 0 | E10: ='Nota de venta'!F11 -> 0 | F10: 1.5 | G10: =TablaOpTelas[[#This Row],[ANCHO]]+(TablaOpTelas[[#This Row],[exc cms x lado]]/100)*2 -> 0.03 | H10: =TablaOpTelas[[#This Row],[ALTO]]+(TablaOpTelas[[#This Row],[exc cms x lado]]/100)*2 -> 0.03 | I10: =TablaOpTelas[[#This Row],[ancho final]]*TablaOpTelas[[#This Row],[alto final]] -> 0.0009 | J10: =TablaOpTelas[[#This Row],[m2 unit]]*TablaOpTelas[[#This Row],['#]] -> 0 | K10: =TablaOpTelas[[#This Row],[ANCHO]]*TablaOpTelas[[#This Row],[ALTO]]*$J$6 -> 0 | L10: =IF($J$7="CAJA TERMINADA",TablaOpTelas[[#This Row],[ANCHO]]+0.013,TablaOpTelas[[#This Row],[ANCHO]]+0.023) -> 0.013 | M10: =IF($J$7="CAJA TERMINADA",TablaOpTelas[[#This Row],[ALTO]]+0.013,TablaOpTelas[[#This Row],[ALTO]]+0.023) -> 0.013 | N10: ='Nota de venta'!L11 -> 0
A11: 3 | B11: ='Nota de venta'!C12 -> 0 | C11: ='Nota de venta'!G12 -> 0 | D11: ='Nota de venta'!E12 -> 0 | E11: ='Nota de venta'!F12 -> 0 | F11: 1.5 | G11: =TablaOpTelas[[#This Row],[ANCHO]]+(TablaOpTelas[[#This Row],[exc cms x lado]]/100)*2 -> 0.03 | H11: =TablaOpTelas[[#This Row],[ALTO]]+(TablaOpTelas[[#This Row],[exc cms x lado]]/100)*2 -> 0.03 | I11: =TablaOpTelas[[#This Row],[ancho final]]*TablaOpTelas[[#This Row],[alto final]] -> 0.0009 | J11: =TablaOpTelas[[#This Row],[m2 unit]]*TablaOpTelas[[#This Row],['#]] -> 0 | K11: =TablaOpTelas[[#This Row],[ANCHO]]*TablaOpTelas[[#This Row],[ALTO]]*$J$6 -> 0 | L11: =IF($J$7="CAJA TERMINADA",TablaOpTelas[[#This Row],[ANCHO]]+0.013,TablaOpTelas[[#This Row],[ANCHO]]+0.023) -> 0.013 | M11: =IF($J$7="CAJA TERMINADA",TablaOpTelas[[#This Row],[ALTO]]+0.013,TablaOpTelas[[#This Row],[ALTO]]+0.023) -> 0.013 | N11: ='Nota de venta'!L12 -> 0
A12: 4 | B12: ='Nota de venta'!C13 -> 0 | C12: ='Nota de venta'!G13 -> 0 | D12: ='Nota de venta'!E13 -> 0 | E12: ='Nota de venta'!F13 -> 0 | F12: 1.5 | G12: =TablaOpTelas[[#This Row],[ANCHO]]+(TablaOpTelas[[#This Row],[exc cms x lado]]/100)*2 -> 0.03 | H12: =TablaOpTelas[[#This Row],[ALTO]]+(TablaOpTelas[[#This Row],[exc cms x lado]]/100)*2 -> 0.03 | I12: =TablaOpTelas[[#This Row],[ancho final]]*TablaOpTelas[[#This Row],[alto final]] -> 0.0009 | J12: =TablaOpTelas[[#This Row],[m2 unit]]*TablaOpTelas[[#This Row],['#]] -> 0 | K12: =TablaOpTelas[[#This Row],[ANCHO]]*TablaOpTelas[[#This Row],[ALTO]]*$J$6 -> 0 | L12: =IF($J$7="CAJA TERMINADA",TablaOpTelas[[#This Row],[ANCHO]]+0.013,TablaOpTelas[[#This Row],[ANCHO]]+0.023) -> 0.013 | M12: =IF($J$7="CAJA TERMINADA",TablaOpTelas[[#This Row],[ALTO]]+0.013,TablaOpTelas[[#This Row],[ALTO]]+0.023) -> 0.013 | N12: ='Nota de venta'!L13 -> 0
A13: 5 | B13: ='Nota de venta'!C14 -> 0 | C13: ='Nota de venta'!G14 -> 0 | D13: ='Nota de venta'!E14 -> 0 | E13: ='Nota de venta'!F14 -> 0 | F13: 1.5 | G13: =TablaOpTelas[[#This Row],[ANCHO]]+(TablaOpTelas[[#This Row],[exc cms x lado]]/100)*2 -> 0.03 | H13: =TablaOpTelas[[#This Row],[ALTO]]+(TablaOpTelas[[#This Row],[exc cms x lado]]/100)*2 -> 0.03 | I13: =TablaOpTelas[[#This Row],[ancho final]]*TablaOpTelas[[#This Row],[alto final]] -> 0.0009 | J13: =TablaOpTelas[[#This Row],[m2 unit]]*TablaOpTelas[[#This Row],['#]] -> 0 | K13: =TablaOpTelas[[#This Row],[ANCHO]]*TablaOpTelas[[#This Row],[ALTO]]*$J$6 -> 0 | L13: =IF($J$7="CAJA TERMINADA",TablaOpTelas[[#This Row],[ANCHO]]+0.013,TablaOpTelas[[#This Row],[ANCHO]]+0.023) -> 0.013 | M13: =IF($J$7="CAJA TERMINADA",TablaOpTelas[[#This Row],[ALTO]]+0.013,TablaOpTelas[[#This Row],[ALTO]]+0.023) -> 0.013 | N13: ='Nota de venta'!L14 -> 0
A14: 6 | B14: ='Nota de venta'!C15 -> 0 | C14: ='Nota de venta'!G15 -> 0 | D14: ='Nota de venta'!E15 -> 0 | E14: ='Nota de venta'!F15 -> 0 | F14: 1.5 | G14: =TablaOpTelas[[#This Row],[ANCHO]]+(TablaOpTelas[[#This Row],[exc cms x lado]]/100)*2 -> 0.03 | H14: =TablaOpTelas[[#This Row],[ALTO]]+(TablaOpTelas[[#This Row],[exc cms x lado]]/100)*2 -> 0.03 | I14: =TablaOpTelas[[#This Row],[ancho final]]*TablaOpTelas[[#This Row],[alto final]] -> 0.0009 | J14: =TablaOpTelas[[#This Row],[m2 unit]]*TablaOpTelas[[#This Row],['#]] -> 0 | K14: =TablaOpTelas[[#This Row],[ANCHO]]*TablaOpTelas[[#This Row],[ALTO]]*$J$6 -> 0 | L14: =IF($J$7="CAJA TERMINADA",TablaOpTelas[[#This Row],[ANCHO]]+0.013,TablaOpTelas[[#This Row],[ANCHO]]+0.023) -> 0.013 | M14: =IF($J$7="CAJA TERMINADA",TablaOpTelas[[#This Row],[ALTO]]+0.013,TablaOpTelas[[#This Row],[ALTO]]+0.023) -> 0.013 | N14: ='Nota de venta'!L15 -> 0
A15: 7 | B15: ='Nota de venta'!C16 -> 0 | C15: ='Nota de venta'!G16 -> 0 | D15: ='Nota de venta'!E16 -> 0 | E15: ='Nota de venta'!F16 -> 0 | F15: 1.5 | G15: =TablaOpTelas[[#This Row],[ANCHO]]+(TablaOpTelas[[#This Row],[exc cms x lado]]/100)*2 -> 0.03 | H15: =TablaOpTelas[[#This Row],[ALTO]]+(TablaOpTelas[[#This Row],[exc cms x lado]]/100)*2 -> 0.03 | I15: =TablaOpTelas[[#This Row],[ancho final]]*TablaOpTelas[[#This Row],[alto final]] -> 0.0009 | J15: =TablaOpTelas[[#This Row],[m2 unit]]*TablaOpTelas[[#This Row],['#]] -> 0 | K15: =TablaOpTelas[[#This Row],[ANCHO]]*TablaOpTelas[[#This Row],[ALTO]]*$J$6 -> 0 | L15: =IF($J$7="CAJA TERMINADA",TablaOpTelas[[#This Row],[ANCHO]]+0.013,TablaOpTelas[[#This Row],[ANCHO]]+0.023) -> 0.013 | M15: =IF($J$7="CAJA TERMINADA",TablaOpTelas[[#This Row],[ALTO]]+0.013,TablaOpTelas[[#This Row],[ALTO]]+0.023) -> 0.013 | N15: ='Nota de venta'!L16 -> 0
A16: 8 | B16: ='Nota de venta'!C17 -> 0 | C16: ='Nota de venta'!G17 -> 0 | D16: ='Nota de venta'!E17 -> 0 | E16: ='Nota de venta'!F17 -> 0 | F16: 1.5 | G16: =TablaOpTelas[[#This Row],[ANCHO]]+(TablaOpTelas[[#This Row],[exc cms x lado]]/100)*2 -> 0.03 | H16: =TablaOpTelas[[#This Row],[ALTO]]+(TablaOpTelas[[#This Row],[exc cms x lado]]/100)*2 -> 0.03 | I16: =TablaOpTelas[[#This Row],[ancho final]]*TablaOpTelas[[#This Row],[alto final]] -> 0.0009 | J16: =TablaOpTelas[[#This Row],[m2 unit]]*TablaOpTelas[[#This Row],['#]] -> 0 | K16: =TablaOpTelas[[#This Row],[ANCHO]]*TablaOpTelas[[#This Row],[ALTO]]*$J$6 -> 0 | L16: =IF($J$7="CAJA TERMINADA",TablaOpTelas[[#This Row],[ANCHO]]+0.013,TablaOpTelas[[#This Row],[ANCHO]]+0.023) -> 0.013 | M16: =IF($J$7="CAJA TERMINADA",TablaOpTelas[[#This Row],[ALTO]]+0.013,TablaOpTelas[[#This Row],[ALTO]]+0.023) -> 0.013 | N16: ='Nota de venta'!L17 -> 0
A17: 9 | B17: ='Nota de venta'!C18 -> 0 | C17: ='Nota de venta'!G18 -> 0 | D17: ='Nota de venta'!E18 -> 0 | E17: ='Nota de venta'!F18 -> 0 | F17: 1.5 | G17: =TablaOpTelas[[#This Row],[ANCHO]]+(TablaOpTelas[[#This Row],[exc cms x lado]]/100)*2 -> 0.03 | H17: =TablaOpTelas[[#This Row],[ALTO]]+(TablaOpTelas[[#This Row],[exc cms x lado]]/100)*2 -> 0.03 | I17: =TablaOpTelas[[#This Row],[ancho final]]*TablaOpTelas[[#This Row],[alto final]] -> 0.0009 | J17: =TablaOpTelas[[#This Row],[m2 unit]]*TablaOpTelas[[#This Row],['#]] -> 0 | K17: =TablaOpTelas[[#This Row],[ANCHO]]*TablaOpTelas[[#This Row],[ALTO]]*$J$6 -> 0 | L17: =IF($J$7="CAJA TERMINADA",TablaOpTelas[[#This Row],[ANCHO]]+0.013,TablaOpTelas[[#This Row],[ANCHO]]+0.023) -> 0.013 | M17: =IF($J$7="CAJA TERMINADA",TablaOpTelas[[#This Row],[ALTO]]+0.013,TablaOpTelas[[#This Row],[ALTO]]+0.023) -> 0.013 | N17: ='Nota de venta'!L18 -> 0
A18: 10 | B18: ='Nota de venta'!C19 -> 0 | C18: ='Nota de venta'!G19 -> 0 | D18: ='Nota de venta'!E19 -> 0 | E18: ='Nota de venta'!F19 -> 0 | F18: 1.5 | G18: =TablaOpTelas[[#This Row],[ANCHO]]+(TablaOpTelas[[#This Row],[exc cms x lado]]/100)*2 -> 0.03 | H18: =TablaOpTelas[[#This Row],[ALTO]]+(TablaOpTelas[[#This Row],[exc cms x lado]]/100)*2 -> 0.03 | I18: =TablaOpTelas[[#This Row],[ancho final]]*TablaOpTelas[[#This Row],[alto final]] -> 0.0009 | J18: =TablaOpTelas[[#This Row],[m2 unit]]*TablaOpTelas[[#This Row],['#]] -> 0 | K18: =TablaOpTelas[[#This Row],[ANCHO]]*TablaOpTelas[[#This Row],[ALTO]]*$J$6 -> 0 | L18: =IF($J$7="CAJA TERMINADA",TablaOpTelas[[#This Row],[ANCHO]]+0.013,TablaOpTelas[[#This Row],[ANCHO]]+0.023) -> 0.013 | M18: =IF($J$7="CAJA TERMINADA",TablaOpTelas[[#This Row],[ALTO]]+0.013,TablaOpTelas[[#This Row],[ALTO]]+0.023) -> 0.013 | N18: ='Nota de venta'!L19 -> 0
A19: 11 | B19: ='Nota de venta'!C20 -> 0 | C19: ='Nota de venta'!G20 -> 0 | D19: ='Nota de venta'!E20 -> 0 | E19: ='Nota de venta'!F20 -> 0 | F19: 1.5 | G19: =TablaOpTelas[[#This Row],[ANCHO]]+(TablaOpTelas[[#This Row],[exc cms x lado]]/100)*2 -> 0.03 | H19: =TablaOpTelas[[#This Row],[ALTO]]+(TablaOpTelas[[#This Row],[exc cms x lado]]/100)*2 -> 0.03 | I19: =TablaOpTelas[[#This Row],[ancho final]]*TablaOpTelas[[#This Row],[alto final]] -> 0.0009 | J19: =TablaOpTelas[[#This Row],[m2 unit]]*TablaOpTelas[[#This Row],['#]] -> 0 | K19: =TablaOpTelas[[#This Row],[ANCHO]]*TablaOpTelas[[#This Row],[ALTO]]*$J$6 -> 0 | L19: =IF($J$7="CAJA TERMINADA",TablaOpTelas[[#This Row],[ANCHO]]+0.013,TablaOpTelas[[#This Row],[ANCHO]]+0.023) -> 0.013 | M19: =IF($J$7="CAJA TERMINADA",TablaOpTelas[[#This Row],[ALTO]]+0.013,TablaOpTelas[[#This Row],[ALTO]]+0.023) -> 0.013 | N19: ='Nota de venta'!L20 -> 0
A20: 12 | B20: ='Nota de venta'!C21 -> 0 | C20: ='Nota de venta'!G21 -> 0 | D20: ='Nota de venta'!E21 -> 0 | E20: ='Nota de venta'!F21 -> 0 | F20: 1.5 | G20: =TablaOpTelas[[#This Row],[ANCHO]]+(TablaOpTelas[[#This Row],[exc cms x lado]]/100)*2 -> 0.03 | H20: =TablaOpTelas[[#This Row],[ALTO]]+(TablaOpTelas[[#This Row],[exc cms x lado]]/100)*2 -> 0.03 | I20: =TablaOpTelas[[#This Row],[ancho final]]*TablaOpTelas[[#This Row],[alto final]] -> 0.0009 | J20: =TablaOpTelas[[#This Row],[m2 unit]]*TablaOpTelas[[#This Row],['#]] -> 0 | K20: =TablaOpTelas[[#This Row],[ANCHO]]*TablaOpTelas[[#This Row],[ALTO]]*$J$6 -> 0 | L20: =IF($J$7="CAJA TERMINADA",TablaOpTelas[[#This Row],[ANCHO]]+0.013,TablaOpTelas[[#This Row],[ANCHO]]+0.023) -> 0.013 | M20: =IF($J$7="CAJA TERMINADA",TablaOpTelas[[#This Row],[ALTO]]+0.013,TablaOpTelas[[#This Row],[ALTO]]+0.023) -> 0.013 | N20: ='Nota de venta'!L21 -> 0
... A107: 99 | B107: ='Nota de venta'!C108 -> 0 | C107: ='Nota de venta'!G108 -> 0 | D107: ='Nota de venta'!E108 -> 0 | E107: ='Nota de venta'!F108 -> 0 | F107: 1.5 | G107: =TablaOpTelas[[#This Row],[ANCHO]]+(TablaOpTelas[[#This Row],[exc cms x lado]]/100)*2 -> 0.03 | H107: =TablaOpTelas[[#This Row],[ALTO]]+(TablaOpTelas[[#This Row],[exc cms x lado]]/100)*2 -> 0.03 | I107: =TablaOpTelas[[#This Row],[ancho final]]*TablaOpTelas[[#This Row],[alto final]] -> 0.0009 | J107: =TablaOpTelas[[#This Row],[m2 unit]]*TablaOpTelas[[#This Row],['#]] -> 0 | K107: =TablaOpTelas[[#This Row],[ANCHO]]*TablaOpTelas[[#This Row],[ALTO]]*$J$6 -> 0 | L107: =IF($J$7="CAJA TERMINADA",TablaOpTelas[[#This Row],[ANCHO]]+0.013,TablaOpTelas[[#This Row],[ANCHO]]+0.023) -> 0.013 | M107: =IF($J$7="CAJA TERMINADA",TablaOpTelas[[#This Row],[ALTO]]+0.013,TablaOpTelas[[#This Row],[ALTO]]+0.023) -> 0.013 | N107: ='Nota de venta'!L108 -> 0
A108: 100 | B108: ='Nota de venta'!C110 -> 0 | C108: ='Nota de venta'!G109 -> 0 | D108: ='Nota de venta'!E110 -> 0 | E108: ='Nota de venta'!F110 -> 0 | F108: 1.5 | G108: =TablaOpTelas[[#This Row],[ANCHO]]+(TablaOpTelas[[#This Row],[exc cms x lado]]/100)*2 -> 0.03 | H108: =TablaOpTelas[[#This Row],[ALTO]]+(TablaOpTelas[[#This Row],[exc cms x lado]]/100)*2 -> 0.03 | I108: =TablaOpTelas[[#This Row],[ancho final]]*TablaOpTelas[[#This Row],[alto final]] -> 0.0009 | J108: =TablaOpTelas[[#This Row],[m2 unit]]*TablaOpTelas[[#This Row],['#]] -> 0 | K108: =TablaOpTelas[[#This Row],[ANCHO]]*TablaOpTelas[[#This Row],[ALTO]]*$J$6 -> 0 | L108: =IF($J$7="CAJA TERMINADA",TablaOpTelas[[#This Row],[ANCHO]]+0.013,TablaOpTelas[[#This Row],[ANCHO]]+0.023) -> 0.013 | M108: =IF($J$7="CAJA TERMINADA",TablaOpTelas[[#This Row],[ALTO]]+0.013,TablaOpTelas[[#This Row],[ALTO]]+0.023) -> 0.013 | N108: ='Nota de venta'!L110 -> 0
C109: =SUM(TablaOpTelas['#]) -> 0 | J109: =SUM(TablaOpTelas[m2 total]) -> 0
B110: Nº INGRESO:
B112: PLOTTER:
B114: ML REQUERIDOS | C114: =J109/'Nota de venta'!D10 -> #VALUE!

Sheet hoja1
C1: ORDEN DE PRODUCCIÓN | G1: Nº: | Z1: Venta Directa | AC1: RC Ferias | AF1: Inser
U2: E-Mail | V2: Sí | W2: Directo | X2: Tela | Y2: Valor Mínimo | Z2: 3-50 m2 | AA2: 51-100 m2 | AB2: 101-200 m2 | AC2: 3-50 m2 | AD2: 51-100 m2 | AE2: 101-200 m2 | AF2: 3-100 m2 | AG2: 101-300 m2 | AH2: Pop Up | AI2: Simple | AJ2: Manual
A3: Fecha: | C3: Fecha de Entrega: | G3: Hora Entrega: | U3: CD/DVD | V3: No | W3: RC Ferias | X3: 3304 - Bandera | Y3: 35000 | Z3: 14000 | AA3: 12500 | AB3: 10500 | AC3: 11000 | AD3: 9500 | AE3: 8000 | AF3: 9500 | AG3: 8000 | AH3: Roller | AI3: Doble | AJ3: Sellado
U4: Laser | W4: Inser | X4: 3306 - Mesh Mate | Y4: 36000 | Z4: 15000 | AA4: 13000 | AB4: 11500 | AC4: 11500 | AD4: 10000 | AE4: 9000 | AF4: 10000 | AG4: 9000 | AH4: Pendón
A5: DATOS CLIENTE | U5: Otros | X5: 3307 - Mesh Brillante | Y5: 36000 | Z5: 15000 | AA5: 13000 | AB5: 11500 | AC5: 11500 | AD5: 10000 | AE5: 9000 | AF5: 10000 | AG5: 9000 | AH5: Bandera
A6: Agencia: | C6: Cliente: | G6: Tema: | X6: 3302 - Satín | Y6: 40000 | Z6: 15500 | AA6: 13500 | AB6: 12000 | AC6: 12000 | AD6: 11000 | AE6: 10000 | AF6: 11000 | AG6: 10000 | AH6: Panel
A7: O. Compra: | C7: Contacto: | G7: Fono: | X7: 3308 - Perforado | Y7: 40000 | Z7: 16000 | AA7: 14000 | AB7: 12500 | AC7: 12500 | AD7: 11500 | AE7: 10500 | AF7: 11500 | AG7: 10500 | AH7: Otros
A8: Cotización: | C8: RUT: | G8: E-Mail: | X8: 3309 - Canvas | Y8: 40000 | Z8: 16500 | AA8: 14500 | AB8: 13000 | AC8: 13000 | AD8: 12000 | AE8: 11000 | AF8: 12000 | AG8: 11000
A9: Vendedor: | C9: Guías: | G9: Fuente: | X9: 3340 - Popelina | Y9: 45000 | Z9: 17000 | AA9: 15000 | AB9: 14000 | AC9: 14000 | AD9: 13000 | AE9: 12000 | AF9: 13000 | AG9: 12000
A11: ITEM DE INGRESO
B12: Observaciones:
A14: PRE-PRENSA
A15: Operador: | C15: Pantones:
A16: Observaciones:
A18: IMPRESIÓN
A19: Máquina: | C19: VºBº | E19: Fecha VºBº | G19: Hora VºBº
A21: REQUERIMIENTO
A22: Nº | B22: Tela | C22: Largo | D22: Alto | E22: Cantidad | F22: Total | G22: Valor Unitario | H22: Valor Total
A23: 1 | F23: =IF(LEN(C23)=0,"",ROUNDUP(E23*D23*C23,0)) | G23: =IF(LEN(B23)=0,"",IF($H$9=$W$2,IF(B23=$X$3,IF(F23<51,$Z$3,IF(F23>100,$AB$3,$AA$3)),IF(B23=$X$4,IF(F23<51,$Z$4,IF(F23>100,$AB$4,$AA$4)),IF(B23=$X$5,IF(F23<51,$Z$5,IF(F23>100,$AB$5,$AA$5)),IF(B23=$X$6,IF(F23<51,$Z$6,IF(F23>100,$AB$6,$AA$6)),IF(B23=$X$7,IF(F23<51,$Z$7,IF(F23>100,$AB$7,$AA$7)),IF(B23=$X$8,IF(F23<51,$Z$8,IF(F23>100,$AB$8,$AA$8)),IF(B23=$X$9,IF(F23<51,$Z$9,IF(F23>100,$AB$9,$AA$9))))))))),IF($H$9=$W$3,IF(B23=$X$3,IF(F23<51,$AC$3,IF(F23>100,$AE$3,$AD$3)),IF(B23=$X$4,IF(F23<51,$AC$4,IF(F23>100,$AE$4,$AD$4)),IF(B23=$X$5,IF(F23<51,$AC$5,IF(F23>100,$AE$5,$AD$5)),IF(B23=$X$6,IF(F23<51,$AC$6,IF(F23>100,$AE$6,$AD$6)),IF(B23=$X$7,IF(F23<51,$AC$7,IF(F23>100,$AE$7,$AD$7)),IF(B23=$X$8,IF(F23<51,$AC$8,IF(F23>100,$AE$8,$AD$8)),IF(B23=$X$9,IF(F23<51,$AC$9,IF(F23>100,$AE$9,$AD$9))))))))),IF($H$9=$W$4,IF(B23=$X$3,IF(F23<101,$AF$3,$AG$3),IF(B23=$X$4,IF(F23<101,$AF$4,$AG$4),IF(B23=$X$5,IF(F23<101,$AF$5,$AG$5),IF(B23=$X$6,IF(F23<101,$AF$6,$AG$6),IF(B23=$X$7,IF(F23<101,$AF$7,$AG$7),IF(B23=$X$8,IF(F23<101,$AF$8,$AG$8),IF(B23=$X$9,IF(F23<101,$AF$9,$AG$9)))))))))))) | H23: =IF(LEN(D23)=0,"",IF(B23=$X$3,IF(F23*G23<$Y$3,$Y$3,F23*G23),IF(B23=$X$4,IF(F23*G23<$Y$4,$Y$4,F23*G23),IF(B23=$X$5,IF(F23*G23<$Y$5,$Y$5,F23*G23),IF(B23=$X$6,IF(F23*G23<$Y$6,$Y$6,F23*G23),IF(B23=$X$7,IF(F23*G23<$Y$7,$Y$7,F23*G23),IF(B23=$X$8,IF(F23*G23<$Y$8,$Y$8,F23*G23),IF(B23=$X$9,IF(F23*G23<$Y$9,$Y$9,F23*G23)))))))))
A24: 2 | F24: =IF(LEN(C24)=0,"",ROUNDUP(E24*D24*C24,0)) | G24: =IF(LEN(B24)=0,"",IF($H$9=$W$2,IF(B24=$X$3,IF(F24<51,$Z$3,IF(F24>100,$AB$3,$AA$3)),IF(B24=$X$4,IF(F24<51,$Z$4,IF(F24>100,$AB$4,$AA$4)),IF(B24=$X$5,IF(F24<51,$Z$5,IF(F24>100,$AB$5,$AA$5)),IF(B24=$X$6,IF(F24<51,$Z$6,IF(F24>100,$AB$6,$AA$6)),IF(B24=$X$7,IF(F24<51,$Z$7,IF(F24>100,$AB$7,$AA$7)),IF(B24=$X$8,IF(F24<51,$Z$8,IF(F24>100,$AB$8,$AA$8)),IF(B24=$X$9,IF(F24<51,$Z$9,IF(F24>100,$AB$9,$AA$9))))))))),IF($H$9=$W$3,IF(B24=$X$3,IF(F24<51,$AC$3,IF(F24>100,$AE$3,$AD$3)),IF(B24=$X$4,IF(F24<51,$AC$4,IF(F24>100,$AE$4,$AD$4)),IF(B24=$X$5,IF(F24<51,$AC$5,IF(F24>100,$AE$5,$AD$5)),IF(B24=$X$6,IF(F24<51,$AC$6,IF(F24>100,$AE$6,$AD$6)),IF(B24=$X$7,IF(F24<51,$AC$7,IF(F24>100,$AE$7,$AD$7)),IF(B24=$X$8,IF(F24<51,$AC$8,IF(F24>100,$AE$8,$AD$8)),IF(B24=$X$9,IF(F24<51,$AC$9,IF(F24>100,$AE$9,$AD$9))))))))),IF($H$9=$W$4,IF(B24=$X$3,IF(F24<101,$AF$3,$AG$3),IF(B24=$X$4,IF(F24<101,$AF$4,$AG$4),IF(B24=$X$5,IF(F24<101,$AF$5,$AG$5),IF(B24=$X$6,IF(F24<101,$AF$6,$AG$6),IF(B24=$X$7,IF(F24<101,$AF$7,$AG$7),IF(B24=$X$8,IF(F24<101,$AF$8,$AG$8),IF(B24=$X$9,IF(F24<101,$AF$9,$AG$9)))))))))))) | H24: =IF(LEN(D24)=0,"",IF(B24=$X$3,IF(F24*G24<$Y$3,$Y$3,F24*G24),IF(B24=$X$4,IF(F24*G24<$Y$4,$Y$4,F24*G24),IF(B24=$X$5,IF(F24*G24<$Y$5,$Y$5,F24*G24),IF(B24=$X$6,IF(F24*G24<$Y$6,$Y$6,F24*G24),IF(B24=$X$7,IF(F24*G24<$Y$7,$Y$7,F24*G24),IF(B24=$X$8,IF(F24*G24<$Y$8,$Y$8,F24*G24),IF(B24=$X$9,IF(F24*G24<$Y$9,$Y$9,F24*G24)))))))))
A25: 3 | F25: =IF(LEN(C25)=0,"",ROUNDUP(E25*D25*C25,0)) | G25: =IF(LEN(B25)=0,"",IF($H$9=$W$2,IF(B25=$X$3,IF(F25<51,$Z$3,IF(F25>100,$AB$3,$AA$3)),IF(B25=$X$4,IF(F25<51,$Z$4,IF(F25>100,$AB$4,$AA$4)),IF(B25=$X$5,IF(F25<51,$Z$5,IF(F25>100,$AB$5,$AA$5)),IF(B25=$X$6,IF(F25<51,$Z$6,IF(F25>100,$AB$6,$AA$6)),IF(B25=$X$7,IF(F25<51,$Z$7,IF(F25>100,$AB$7,$AA$7)),IF(B25=$X$8,IF(F25<51,$Z$8,IF(F25>100,$AB$8,$AA$8)),IF(B25=$X$9,IF(F25<51,$Z$9,IF(F25>100,$AB$9,$AA$9))))))))),IF($H$9=$W$3,IF(B25=$X$3,IF(F25<51,$AC$3,IF(F25>100,$AE$3,$AD$3)),IF(B25=$X$4,IF(F25<51,$AC$4,IF(F25>100,$AE$4,$AD$4)),IF(B25=$X$5,IF(F25<51,$AC$5,IF(F25>100,$AE$5,$AD$5)),IF(B25=$X$6,IF(F25<51,$AC$6,IF(F25>100,$AE$6,$AD$6)),IF(B25=$X$7,IF(F25<51,$AC$7,IF(F25>100,$AE$7,$AD$7)),IF(B25=$X$8,IF(F25<51,$AC$8,IF(F25>100,$AE$8,$AD$8)),IF(B25=$X$9,IF(F25<51,$AC$9,IF(F25>100,$AE$9,$AD$9))))))))),IF($H$9=$W$4,IF(B25=$X$3,IF(F25<101,$AF$3,$AG$3),IF(B25=$X$4,IF(F25<101,$AF$4,$AG$4),IF(B25=$X$5,IF(F25<101,$AF$5,$AG$5),IF(B25=$X$6,IF(F25<101,$AF$6,$AG$6),IF(B25=$X$7,IF(F25<101,$AF$7,$AG$7),IF(B25=$X$8,IF(F25<101,$AF$8,$AG$8),IF(B25=$X$9,IF(F25<101,$AF$9,$AG$9)))))))))))) | H25: =IF(LEN(D25)=0,"",IF(B25=$X$3,IF(F25*G25<$Y$3,$Y$3,F25*G25),IF(B25=$X$4,IF(F25*G25<$Y$4,$Y$4,F25*G25),IF(B25=$X$5,IF(F25*G25<$Y$5,$Y$5,F25*G25),IF(B25=$X$6,IF(F25*G25<$Y$6,$Y$6,F25*G25),IF(B25=$X$7,IF(F25*G25<$Y$7,$Y$7,F25*G25),IF(B25=$X$8,IF(F25*G25<$Y$8,$Y$8,F25*G25),IF(B25=$X$9,IF(F25*G25<$Y$9,$Y$9,F25*G25)))))))))
A26: 4 | F26: =IF(LEN(C26)=0,"",ROUNDUP(E26*D26*C26,0)) | G26: =IF(LEN(B26)=0,"",IF($H$9=$W$2,IF(B26=$X$3,IF(F26<51,$Z$3,IF(F26>100,$AB$3,$AA$3)),IF(B26=$X$4,IF(F26<51,$Z$4,IF(F26>100,$AB$4,$AA$4)),IF(B26=$X$5,IF(F26<51,$Z$5,IF(F26>100,$AB$5,$AA$5)),IF(B26=$X$6,IF(F26<51,$Z$6,IF(F26>100,$AB$6,$AA$6)),IF(B26=$X$7,IF(F26<51,$Z$7,IF(F26>100,$AB$7,$AA$7)),IF(B26=$X$8,IF(F26<51,$Z$8,IF(F26>100,$AB$8,$AA$8)),IF(B26=$X$9,IF(F26<51,$Z$9,IF(F26>100,$AB$9,$AA$9))))))))),IF($H$9=$W$3,IF(B26=$X$3,IF(F26<51,$AC$3,IF(F26>100,$AE$3,$AD$3)),IF(B26=$X$4,IF(F26<51,$AC$4,IF(F26>100,$AE$4,$AD$4)),IF(B26=$X$5,IF(F26<51,$AC$5,IF(F26>100,$AE$5,$AD$5)),IF(B26=$X$6,IF(F26<51,$AC$6,IF(F26>100,$AE$6,$AD$6)),IF(B26=$X$7,IF(F26<51,$AC$7,IF(F26>100,$AE$7,$AD$7)),IF(B26=$X$8,IF(F26<51,$AC$8,IF(F26>100,$AE$8,$AD$8)),IF(B26=$X$9,IF(F26<51,$AC$9,IF(F26>100,$AE$9,$AD$9))))))))),IF($H$9=$W$4,IF(B26=$X$3,IF(F26<101,$AF$3,$AG$3),IF(B26=$X$4,IF(F26<101,$AF$4,$AG$4),IF(B26=$X$5,IF(F26<101,$AF$5,$AG$5),IF(B26=$X$6,IF(F26<101,$AF$6,$AG$6),IF(B26=$X$7,IF(F26<101,$AF$7,$AG$7),IF(B26=$X$8,IF(F26<101,$AF$8,$AG$8),IF(B26=$X$9,IF(F26<101,$AF$9,$AG$9)))))))))))) | H26: =IF(LEN(D26)=0,"",IF(B26=$X$3,IF(F26*G26<$Y$3,$Y$3,F26*G26),IF(B26=$X$4,IF(F26*G26<$Y$4,$Y$4,F26*G26),IF(B26=$X$5,IF(F26*G26<$Y$5,$Y$5,F26*G26),IF(B26=$X$6,IF(F26*G26<$Y$6,$Y$6,F26*G26),IF(B26=$X$7,IF(F26*G26<$Y$7,$Y$7,F26*G26),IF(B26=$X$8,IF(F26*G26<$Y$8,$Y$8,F26*G26),IF(B26=$X$9,IF(F26*G26<$Y$9,$Y$9,F26*G26)))))))))
A27: 5 | F27: =IF(LEN(C27)=0,"",ROUNDUP(E27*D27*C27,0)) | G27: =IF(LEN(B27)=0,"",IF($H$9=$W$2,IF(B27=$X$3,IF(F27<51,$Z$3,IF(F27>100,$AB$3,$AA$3)),IF(B27=$X$4,IF(F27<51,$Z$4,IF(F27>100,$AB$4,$AA$4)),IF(B27=$X$5,IF(F27<51,$Z$5,IF(F27>100,$AB$5,$AA$5)),IF(B27=$X$6,IF(F27<51,$Z$6,IF(F27>100,$AB$6,$AA$6)),IF(B27=$X$7,IF(F27<51,$Z$7,IF(F27>100,$AB$7,$AA$7)),IF(B27=$X$8,IF(F27<51,$Z$8,IF(F27>100,$AB$8,$AA$8)),IF(B27=$X$9,IF(F27<51,$Z$9,IF(F27>100,$AB$9,$AA$9))))))))),IF($H$9=$W$3,IF(B27=$X$3,IF(F27<51,$AC$3,IF(F27>100,$AE$3,$AD$3)),IF(B27=$X$4,IF(F27<51,$AC$4,IF(F27>100,$AE$4,$AD$4)),IF(B27=$X$5,IF(F27<51,$AC$5,IF(F27>100,$AE$5,$AD$5)),IF(B27=$X$6,IF(F27<51,$AC$6,IF(F27>100,$AE$6,$AD$6)),IF(B27=$X$7,IF(F27<51,$AC$7,IF(F27>100,$AE$7,$AD$7)),IF(B27=$X$8,IF(F27<51,$AC$8,IF(F27>100,$AE$8,$AD$8)),IF(B27=$X$9,IF(F27<51,$AC$9,IF(F27>100,$AE$9,$AD$9))))))))),IF($H$9=$W$4,IF(B27=$X$3,IF(F27<101,$AF$3,$AG$3),IF(B27=$X$4,IF(F27<101,$AF$4,$AG$4),IF(B27=$X$5,IF(F27<101,$AF$5,$AG$5),IF(B27=$X$6,IF(F27<101,$AF$6,$AG$6),IF(B27=$X$7,IF(F27<101,$AF$7,$AG$7),IF(B27=$X$8,IF(F27<101,$AF$8,$AG$8),IF(B27=$X$9,IF(F27<101,$AF$9,$AG$9)))))))))))) | H27: =IF(LEN(D27)=0,"",IF(B27=$X$3,IF(F27*G27<$Y$3,$Y$3,F27*G27),IF(B27=$X$4,IF(F27*G27<$Y$4,$Y$4,F27*G27),IF(B27=$X$5,IF(F27*G27<$Y$5,$Y$5,F27*G27),IF(B27=$X$6,IF(F27*G27<$Y$6,$Y$6,F27*G27),IF(B27=$X$7,IF(F27*G27<$Y$7,$Y$7,F27*G27),IF(B27=$X$8,IF(F27*G27<$Y$8,$Y$8,F27*G27),IF(B27=$X$9,IF(F27*G27<$Y$9,$Y$9,F27*G27)))))))))
A28: 6 | F28: =IF(LEN(C28)=0,"",ROUNDUP(E28*D28*C28,0)) | G28: =IF(LEN(B28)=0,"",IF($H$9=$W$2,IF(B28=$X$3,IF(F28<51,$Z$3,IF(F28>100,$AB$3,$AA$3)),IF(B28=$X$4,IF(F28<51,$Z$4,IF(F28>100,$AB$4,$AA$4)),IF(B28=$X$5,IF(F28<51,$Z$5,IF(F28>100,$AB$5,$AA$5)),IF(B28=$X$6,IF(F28<51,$Z$6,IF(F28>100,$AB$6,$AA$6)),IF(B28=$X$7,IF(F28<51,$Z$7,IF(F28>100,$AB$7,$AA$7)),IF(B28=$X$8,IF(F28<51,$Z$8,IF(F28>100,$AB$8,$AA$8)),IF(B28=$X$9,IF(F28<51,$Z$9,IF(F28>100,$AB$9,$AA$9))))))))),IF($H$9=$W$3,IF(B28=$X$3,IF(F28<51,$AC$3,IF(F28>100,$AE$3,$AD$3)),IF(B28=$X$4,IF(F28<51,$AC$4,IF(F28>100,$AE$4,$AD$4)),IF(B28=$X$5,IF(F28<51,$AC$5,IF(F28>100,$AE$5,$AD$5)),IF(B28=$X$6,IF(F28<51,$AC$6,IF(F28>100,$AE$6,$AD$6)),IF(B28=$X$7,IF(F28<51,$AC$7,IF(F28>100,$AE$7,$AD$7)),IF(B28=$X$8,IF(F28<51,$AC$8,IF(F28>100,$AE$8,$AD$8)),IF(B28=$X$9,IF(F28<51,$AC$9,IF(F28>100,$AE$9,$AD$9))))))))),IF($H$9=$W$4,IF(B28=$X$3,IF(F28<101,$AF$3,$AG$3),IF(B28=$X$4,IF(F28<101,$AF$4,$AG$4),IF(B28=$X$5,IF(F28<101,$AF$5,$AG$5),IF(B28=$X$6,IF(F28<101,$AF$6,$AG$6),IF(B28=$X$7,IF(F28<101,$AF$7,$AG$7),IF(B28=$X$8,IF(F28<101,$AF$8,$AG$8),IF(B28=$X$9,IF(F28<101,$AF$9,$AG$9)))))))))))) | H28: =IF(LEN(D28)=0,"",IF(B28=$X$3,IF(F28*G28<$Y$3,$Y$3,F28*G28),IF(B28=$X$4,IF(F28*G28<$Y$4,$Y$4,F28*G28),IF(B28=$X$5,IF(F28*G28<$Y$5,$Y$5,F28*G28),IF(B28=$X$6,IF(F28*G28<$Y$6,$Y$6,F28*G28),IF(B28=$X$7,IF(F28*G28<$Y$7,$Y$7,F28*G28),IF(B28=$X$8,IF(F28*G28<$Y$8,$Y$8,F28*G28),IF(B28=$X$9,IF(F28*G28<$Y$9,$Y$9,F28*G28)))))))))
G29: Sub-Total | H29: =SUM(H23:H28) -> 0
A31: DESCRIPCIÓN DEL TRABAJO
A32: Soporte: | E32: Plantilla Cliente:
A34: TERMINACIONES
A35: Soporte: | C35: Observaciones:
A36: Medida Vivo:
A37: Costura:
A38: Tamaño Bolsillo:
A39: Tipo de Corte:
A40: Ojetillos
A41: Remaches
A42: Tipo Travesaño: | C42: Valor de las Terminaciones:

Sheet OP cajas
D1: Nº OP | E1: ='Nota de venta'!H1 -> 0
D4: ='Nota de venta'!C112 -> 0
D6: ='Nota de venta'!C6 -> 0
G7: Ingreso | H7: 0
G8: Entrega | H8: 0
A9: Cantidad | B9: Producto | C9: Ancho | D9: Alto | E9: materiales | F9: tipo | G9: cantidad x caja | H9: cantidad total
A10: =+'NV CAJAS (BL)'!D16 -> 0 | B10: =+'NV CAJAS (BL)'!C16 -> 0 | C10: ='Nota de venta'!E10 -> 0 | D10: ='Nota de venta'!F10 -> 0 | E10: Perfil | F10: =+'NV CAJAS (BL)'!Y16 | G10: =+'NV CAJAS (BL)'!T16/I10 -> 0 | H10: =+G10*A10 -> 0 | I10: 6 | J10: ml x perfil
E11: Traseras | F11: =+'NV CAJAS (BL)'!V16 | G11: =+(C10*D10)/I11 -> 0 | H11: =+G11*A10+0.5 -> 0.5 | I11: =1.22*2.44 -> 2.9768 | J11: m2 x trasera
E12: Luces 1 | F12: =+'NV CAJAS (BL)'!H16 | G12: =+'NV CAJAS (BL)'!P16 -> #N/A | H12: =+G12*A10 -> #N/A
A13: OBS: | E13: Luces 2 | F13: =+'NV CAJAS (BL)'!L16 -> sin luces | G13: =+'NV CAJAS (BL)'!Q16 -> 0 | H13: =+G13*A10 -> 0
E14: FP | F14: =+'NV CAJAS (BL)'!W16 -> FALSE | G14: 1 | H14: =+G14*A10 -> 0 | K14: ='NV CAJAS (BL)'!X16 -> #N/A
A15: =+'NV CAJAS (BL)'!D17 -> 0 | B15: =+'NV CAJAS (BL)'!C17 -> 0 | C15: ='Nota de venta'!E11 -> 0 | D15: ='Nota de venta'!F11 -> 0 | E15: Perfil | F15: =+'NV CAJAS (BL)'!Y17 | G15: =+'NV CAJAS (BL)'!T17/I15 -> 0 | H15: =+G15*A15 -> 0 | I15: 6 | J15: ml x perfil
E16: Traseras | F16: =+'NV CAJAS (BL)'!V17 | G16: =+(C15*D15)/I16 -> 0 | H16: =+G16*A15+0.5 -> 0.5 | I16: =1.22*2.44 -> 2.9768 | J16: m2 x trasera
E17: Luces 1 | F17: =+'NV CAJAS (BL)'!H17 | G17: =+'NV CAJAS (BL)'!P17 -> #N/A | H17: =+G17*A15 -> #N/A
A18: OBS: | E18: Luces 2 | F18: =+'NV CAJAS (BL)'!L17 -> sin luces | G18: =+'NV CAJAS (BL)'!Q17 -> 0 | H18: =+G18*A15 -> 0
